ERROR:cfscanner.main:HTTPSConnectionPool(host='raw.githubusercontent.com', port=443): Max retries exceeded with url: /MortezaBashsiz/CFScanner/main/bash/ClientConfig.json (Caused by NewConnectionError('<urllib3.connection.HTTPSConnection object at 0x7fcc11b508e0>: Failed to establish a new connection: [Errno 101] Network is unreachable'))
Traceback (most recent call last):
  File "/home/smz/.local/lib/python3.10/site-packages/urllib3/connection.py", line 174, in _new_conn
    conn = connection.create_connection(
  File "/home/smz/.local/lib/python3.10/site-packages/urllib3/util/connection.py", line 95, in create_connection
    raise err
  File "/home/smz/.local/lib/python3.10/site-packages/urllib3/util/connection.py", line 85, in create_connection
    sock.connect(sa)
OSError: [Errno 101] Network is unreachable

During handling of the above exception, another exception occurred:

Traceback (most recent call last):
  File "/home/smz/.local/lib/python3.10/site-packages/urllib3/connectionpool.py", line 703, in urlopen
    httplib_response = self._make_request(
  File "/home/smz/.local/lib/python3.10/site-packages/urllib3/connectionpool.py", line 386, in _make_request
    self._validate_conn(conn)
  File "/home/smz/.local/lib/python3.10/site-packages/urllib3/connectionpool.py", line 1042, in _validate_conn
    conn.connect()
  File "/home/smz/.local/lib/python3.10/site-packages/urllib3/connection.py", line 363, in connect
    self.sock = conn = self._new_conn()
  File "/home/smz/.local/lib/python3.10/site-packages/urllib3/connection.py", line 186, in _new_conn
    raise NewConnectionError(
urllib3.exceptions.NewConnectionError: <urllib3.connection.HTTPSConnection object at 0x7fcc11b508e0>: Failed to establish a new connection: [Errno 101] Network is unreachable

During handling of the above exception, another exception occurred:

Traceback (most recent call last):
  File "/home/smz/.local/lib/python3.10/site-packages/requests/adapters.py", line 489, in send
    resp = conn.urlopen(
  File "/home/smz/.local/lib/python3.10/site-packages/urllib3/connectionpool.py", line 787, in urlopen
    retries = retries.increment(
  File "/home/smz/.local/lib/python3.10/site-packages/urllib3/util/retry.py", line 592, in increment
    raise MaxRetryError(_pool, url, error or ResponseError(cause))
urllib3.exceptions.MaxRetryError: HTTPSConnectionPool(host='raw.githubusercontent.com', port=443): Max retries exceeded with url: /MortezaBashsiz/CFScanner/main/bash/ClientConfig.json (Caused by NewConnectionError('<urllib3.connection.HTTPSConnection object at 0x7fcc11b508e0>: Failed to establish a new connection: [Errno 101] Network is unreachable'))

During handling of the above exception, another exception occurred:

Traceback (most recent call last):
  File "/home/smz/.local/lib/python3.10/site-packages/cfscanner/main.py", line 149, in main
    test_config = TestConfig.from_args(args)
  File "/home/smz/.local/lib/python3.10/site-packages/cfscanner/args/testconfig.py", line 31, in from_args
    download_file(
  File "/home/smz/.local/lib/python3.10/site-packages/cfscanner/utils/requests.py", line 22, in download_file
    r = requests.get(url, stream=True, timeout=timeout)
  File "/home/smz/.local/lib/python3.10/site-packages/requests/api.py", line 73, in get
    return request("get", url, params=params, **kwargs)
  File "/home/smz/.local/lib/python3.10/site-packages/requests/api.py", line 59, in request
    return session.request(method=method, url=url, **kwargs)
  File "/home/smz/.local/lib/python3.10/site-packages/requests/sessions.py", line 587, in request
    resp = self.send(prep, **send_kwargs)
  File "/home/smz/.local/lib/python3.10/site-packages/requests/sessions.py", line 701, in send
    r = adapter.send(request, **kwargs)
  File "/home/smz/.local/lib/python3.10/site-packages/requests/adapters.py", line 565, in send
    raise ConnectionError(e, request=request)
requests.exceptions.ConnectionError: HTTPSConnectionPool(host='raw.githubusercontent.com', port=443): Max retries exceeded with url: /MortezaBashsiz/CFScanner/main/bash/ClientConfig.json (Caused by NewConnectionError('<urllib3.connection.HTTPSConnection object at 0x7fcc11b508e0>: Failed to establish a new connection: [Errno 101] Network is unreachable'))
